Workbook
Name __xlfn_IFERROR: #N/A
Name Excel_BuiltIn__FilterDatabase: 'Feira Santana'!$A$15:$Q$235

Sheet Custo por transação
B2: Levantamento das Receitas e Custos Transacionais (Jun a Ago/23)
B4: Receitas Médias por Transações
B6: Mês | C6: Transações | D6: Fatur. Bruto | E6: Receita Bruta | F6: Fat./Trans. | G6: Rec./Trans. | H6: Rec. %
B7: 45078 | C7: 675712 | D7: 15995584 | E7: =#REF! -> #REF! | F7: =D7/C7 -> 23.672192 | G7: =E7/C7 -> #REF! | H7: =E7/D7 -> #REF!
B8: 45108 | C8: 751665 | D8: 17966884 | E8: =#REF! -> #REF! | F8: =D8/C8 -> 23.902781 | G8: =E8/C8 -> #REF! | H8: =E8/D8 -> #REF!
B9: 45139 | C9: 851310 | D9: 20565837 | E9: =#REF! -> #REF! | F9: =D9/C9 -> 24.157871 | G9: =E9/C9 -> #REF! | H9: =E9/D9 -> #REF!
B10: Total | C10: =SUM(C7:C9) -> 2278687 | D10: =SUM(D7:D9) -> 54528305 | E10: =SUM(E7:E9) -> #REF! | F10: =D10/C10 -> 23.929704 | G10: =E10/C10 -> #REF! | H10: =E10/D10 -> #REF!
B12: Custos Diretos por Transações*
B14: Mês | C14: Transações | D14: Des. Financ.** | E14: Impostos Dir. | F14: Total | G14: Custo Dir/Trans. | H14: Custo %
B15: =B7 -> 45078 | C15: =C7 -> 675712 | D15: =#REF!+#REF! -> #REF! | E15: =#REF!+E57 -> #REF! | F15: =SUM(D15:E15) -> #REF! | G15: =F15/C15 -> #REF! | H15: =F15/D7 -> #REF!
B16: =B8 -> 45108 | C16: =C8 -> 751665 | D16: =#REF!+#REF! -> #REF! | E16: =#REF!+E58 -> #REF! | F16: =SUM(D16:E16) -> #REF! | G16: =F16/C16 -> #REF! | H16: =F16/D8 -> #REF!
B17: =B9 -> 45139 | C17: =C9 -> 851310 | D17: =#REF!+#REF! -> #REF! | E17: =#REF!+E59 -> #REF! | F17: =SUM(D17:E17) -> #REF! | G17: =F17/C17 -> #REF! | H17: =F17/D9 -> #REF!
B18: Total | C18: =SUM(C15:C17) -> 2278687 | D18: =SUM(D15:D17) -> #REF! | E18: =SUM(E15:E17) -> #REF! | F18: =SUM(F15:F17) -> #REF! | G18: =F18/C18 -> #REF! | H18: =F18/D10 -> #REF!
B19: *ISS ajustado para 5% sobre receita bruta
B20: ** Inclui estornos financeiros e chargeback
B22: Custos Indiretos por Transações
B24: Mês | C24: Transações | D24: Infra de Sistemas | E24: Chips Tim | F24: Delivery | G24: Total | H24: Custo Ind./Trans. | I24: Custo %
B25: =B15 -> 45078 | C25: =C15 -> 675712 | D25: =F51 -> #REF! | E25: =#REF! -> #REF! | F25: =#REF! -> #REF! | G25: =SUM(D25:F25) -> #REF! | H25: =G25/C25 -> #REF! | I25: =G25/D7 -> #REF!
B26: =B16 -> 45108 | C26: =C16 -> 751665 | D26: =G51 -> #REF! | E26: =#REF! -> #REF! | F26: =#REF! -> #REF! | G26: =SUM(D26:F26) -> #REF! | H26: =G26/C26 -> #REF! | I26: =G26/D8 -> #REF!
B27: =B17 -> 45139 | C27: =C17 -> 851310 | D27: =H51 -> #REF! | E27: =#REF! -> #REF! | F27: =#REF! -> #REF! | G27: =SUM(D27:F27) -> #REF! | H27: =G27/C27 -> #REF! | I27: =G27/D9 -> #REF!
B28: Total | C28: =SUM(C25:C27) -> 2278687 | D28: =SUM(D25:D27) -> #REF! | E28: =SUM(E25:E27) -> #REF! | F28: =SUM(F25:F27) -> #REF! | G28: =SUM(G25:G27) -> #REF! | H28: =G28/C28 -> #REF! | I28: =G28/D10 -> #REF!
B30: Custos Administrativos por transação
B32: Mês | C32: Transações | D32: Pessoal* | E32: Viagens | F32: Marketing | G32: Outros | H32: Total | I32: Adm/Trans. | J32: Custo %
B33: =B25 -> 45078 | C33: =C25 -> 675712 | D33: =#REF!+#REF!-#REF! -> #REF! | E33: =#REF! -> #REF! | F33: =#REF! -> #REF! | G33: =#REF!-SUM(D33:F33)-F15-G25 -> #REF! | H33: =SUM(D33:G33) -> #REF! | I33: =H33/C33 -> #REF! | J33: =H33/D7 -> #REF!
B34: =B26 -> 45108 | C34: =C26 -> 751665 | D34: =#REF!+#REF!-#REF! -> #REF! | E34: =#REF! -> #REF! | F34: =#REF! -> #REF! | G34: =#REF!-SUM(D34:F34)-F16-G26 -> #REF! | H34: =SUM(D34:G34) -> #REF! | I34: =H34/C34 -> #REF! | J34: =H34/D8 -> #REF!
B35: =B27 -> 45139 | C35: =C27 -> 851310 | D35: =#REF!+#REF!-#REF! -> #REF! | E35: =#REF! -> #REF! | F35: =#REF! -> #REF! | G35: =#REF!-SUM(D35:F35)-F17-G27 -> #REF! | H35: =SUM(D35:G35) -> #REF! | I35: =H35/C35 -> #REF! | J35: =H35/D9 -> #REF!
B36: Total | C36: =SUM(C33:C35) -> 2278687 | D36: =SUM(D33:D35) -> #REF! | E36: =SUM(E33:E35) -> #REF! | F36: =SUM(F33:F35) -> #REF! | G36: =SUM(G33:G35) -> #REF! | H36: =SUM(D36:G36) -> #REF! | I36: =H36/C36 -> #REF! | J36: =H36/D10 -> #REF!
B37: * Inclui Pjs e Body shop e rateio com BIG
F40: 45078 | G40: 45108 | H40: 45139
B41: Sotwares e Licenças de Uso | F41: =#REF! -> #REF! | G41: =#REF! -> #REF! | H41: =#REF! -> #REF!
B42: =#REF! -> #REF! | F42: =#REF! -> #REF! | G42: =#REF! -> #REF! | H42: =#REF! -> #REF!
B43: =#REF! -> #REF! | F43: =#REF! -> #REF! | G43: =#REF! -> #REF! | H43: =#REF! -> #REF!
B44: =#REF! -> #REF! | F44: =#REF! -> #REF! | G44: =#REF! -> #REF! | H44: =#REF! -> #REF!
B45: =#REF! -> #REF! | F45: =#REF! -> #REF! | G45: =#REF! -> #REF! | H45: =#REF! -> #REF!
B46: =#REF! -> #REF! | F46: =#REF! -> #REF! | G46: =#REF! -> #REF! | H46: =#REF! -> #REF!
B47: =#REF! -> #REF! | F47: =#REF! -> #REF! | G47: =#REF! -> #REF! | H47: =#REF! -> #REF!
B48: =#REF! -> #REF! | F48: =#REF! -> #REF! | G48: =#REF! -> #REF! | H48: =#REF! -> #REF!
B49: =#REF! -> #REF! | F49: =#REF! -> #REF! | G49: =#REF! -> #REF! | H49: =#REF! -> #REF!
B50: =#REF! -> #REF! | F50: =#REF! -> #REF! | G50: =#REF! -> #REF! | H50: =#REF! -> #REF!
B51: Total | F51: =SUM(F41:F50) -> #REF! | G51: =SUM(G41:G50) -> #REF! | H51: =SUM(H41:H50) -> #REF!
...

Sheet Cargos e Tarefas

Sheet Custos
B2: FIXO | G2: VARIAVEL | L2: DIVIDA FORNECEDORES
B4: DIA VENCIMENTO | C4: ORIGEM | D4: VALOR | G4: DIA VENCIMENTO | H4: ORIGEM | I4: VALOR | L4: Mês | M4: Valor
B5: Dia 5 | C5: Despesas Pessoal | D5: 9779 | G5: Dia 10 | H5: Cartão de credito | I5: 5000 | L5: 46023 | M5: =24124 -> 24124
B6: Dia 5 | C6: Retirada (prolabore) | D6: 17000 | G6: Diariamente | H6: Materia prima | I6: 0 | L6: 46054 | M6: ='PLANO ORÇAMENTARIO - VIP'!E15 -> 217067.97
B7: Dia 30 | C7: Consultoria Financeira | D7: 1000 | G7: Dia 10 | H7: Marketing | I7: 3000 | L7: 46082 | M7: ='PLANO ORÇAMENTARIO - VIP'!G15 -> 176833.13
B8: Dia 20 | C8: Consultoria Contabil | D8: 600 | G8: Dia 20 | H8: Impostos | I8: 35000 | L8: 46113 | M8: ='PLANO ORÇAMENTARIO - VIP'!I15 -> 91175.7
B9: Dia 10 | C9: Aluguel + Condominio | D9: 2150 | G9: Diariamente | H9: Taxas das plataformas | I9: 0 | L9: 46143 | M9: ='PLANO ORÇAMENTARIO - VIP'!K15 -> 48922.88
B10: Dia 10 | C10: Luz | D10: 850 | G10: Diariamente | H10: Cancelamentos e reembolsos | I10: 0 | L10: 46174 | M10: ='PLANO ORÇAMENTARIO - VIP'!M15 -> 21761.12
B11: Dia 10 | C11: Agua | D11: 250 | I11: =SUM(I5:I10) -> 43000 | L11: 46204 | M11: ='PLANO ORÇAMENTARIO - VIP'!O15 -> 0
B12: Dia 20 | C12: Bling | D12: 450 | L12: Total: | M12: =SUM(M5:M11) -> 579884.8
B13: Dia 5 | C13: Despesas de venda | D13: 2000
B14: Dia 15 | C14: Financiamento Pronamp | D14: 6602
D15: =SUM(D5:D14) -> 40681
B18: Fornecedores
B19: Nome | C19: Contato | D19: Telefone | E19: Email

Sheet Resumo Gerencial
B5: RESULTADO GRUPO VIP 01-2026 A 12-2026
B7: Empresa | C7: 46023 | D7: 46054 | E7: 46082 | F7: 46113 | G7: 46143 | H7: 46174 | I7: 46204 | J7: 46235 | K7: 46266 | L7: 46296 | M7: 46327 | N7: 46357
B8: Vip | C8: ='PLANO ORÇAMENTARIO - VIP'!D24 -> -4409.78 | D8: ='PLANO ORÇAMENTARIO - VIP'!F24 -> -26198.19 | E8: ='PLANO ORÇAMENTARIO - VIP'!H24 -> -18203.49 | F8: ='PLANO ORÇAMENTARIO - VIP'!J24 -> 136391.74 | G8: ='VIP MX'!G273 -> 0 | H8: ='VIP MX'!H273 -> 0 | I8: ='VIP MX'!I273 -> 0 | J8: ='VIP MX'!J273 -> 0 | K8: ='VIP MX'!K273 -> 0 | L8: ='VIP MX'!L273 -> 0 | M8: ='VIP MX'!M273 -> 0 | N8: ='VIP MX'!N273 -> 0
B9: Vidal | C9: ='PLANO ORÇAMENTARIO - VIDAL'!D24 -> 125409.35 | D9: ='PLANO ORÇAMENTARIO - VIDAL'!F24 -> 80362 | E9: ='PLANO ORÇAMENTARIO - VIDAL'!H24 -> 127304.9 | F9: ='PLANO ORÇAMENTARIO - VIDAL'!J24 -> 115201.03 | G9: =VIDAL!G275 -> 0 | H9: =VIDAL!H275 -> 0 | I9: =VIDAL!I275 -> 0 | J9: =VIDAL!J275 -> 0 | K9: =VIDAL!K275 -> 0 | L9: =VIDAL!L275 -> 0 | M9: =VIDAL!M275 -> 0 | N9: =VIDAL!N275 -> 0
B10: V3 | C10: ='PLANO ORÇAMENTARIO - V3'!D22 -> 2128 | D10: ='PLANO ORÇAMENTARIO - V3'!F22 -> 2771.72 | E10: ='PLANO ORÇAMENTARIO - V3'!H22 -> 2707.46 | F10: ='PLANO ORÇAMENTARIO - V3'!I22 -> 2739.1 | G10: ='V3'!G275 -> 0 | H10: ='V3'!H275 -> 0 | I10: ='V3'!I275 -> 0 | J10: ='V3'!J275 -> 0 | K10: ='V3'!K275 -> 0 | L10: ='V3'!L275 -> 0 | M10: ='V3'!M275 -> 0 | N10: ='V3'!N275 -> 0
B11: Resultado | C11: =C8+C9+C10 -> 123127.57 | D11: =D8+D9+D10 -> 56935.53 | E11: =E8+E9+E10 -> 111808.87 | F11: =F8+F9+F10 -> 254331.87 | G11: =G8+G9+G10 -> 0 | H11: =H8+H9+H10 -> 0 | I11: =I8+I9+I10 -> 0 | J11: =J8+J9+J10 -> 0 | ... N11: =N8+N9+N10 -> 0

Sheet PLANO ORÇAMENTARIO - VIP
A1: VIP MX | C1: Previsto | D1: Realizado | E1: Previsto | F1: Realizado | G1: Previsto | H1: Realizado | I1: Previsto | J1: Realizado | K1: Previsto | L1: Realizado | M1: Previsto | N1: Realizado | O1: Previsto | P1: Realizado | Q1: Previsto | R1: Realizado | S1: Previsto | T1: Realizado | U1: Previsto | V1: Realizado | W1: Previsto | X1: Realizado | Y1: Previsto | Z1: Realizado
C2: 46023 | D2: 46023 | E2: 46054 | F2: 46054 | G2: 46082 | H2: 46082 | I2: 46113 | J2: 46113 | K2: 46143 | L2: 46143 | M2: 46174 | N2: 46174 | O2: 46204 | P2: 46204 | Q2: 46235 | R2: 46235 | S2: 46266 | T2: 46266 | U2: 46296 | V2: 46296 | W2: 46327 | X2: 46327 | Y2: 46357 | Z2: 46357
A3: Receita Bruta | C3: =SUM(C4:C7) -> 266500 | D3: =SUM(D4:D7) -> 435355.47 | E3: =SUM(E4:E7) -> 266500 | F3: =SUM(F4:F7) -> 363193.79 | G3: =SUM(G4:G7) -> 263000 | H3: =SUM(H4:H7) -> 446257.54 | I3: =SUM(I4:I7) -> 293150 | J3: =SUM(J4:J7) -> 545913.33 | ... Z3: =SUM(Z4:Z7) -> 0
A4: VENDAS MERCADO LIVRE - VIP MX | C4: 260000 | D4: 413271.86 | E4: 260000 | F4: 347450.9 | G4: 260000 | H4: 412851.33 | I4: 286000 | J4: =507580.01 -> 507580.01 | K4: 286000 | M4: 286000
A5: VENDAS AMAZON - VIP MX | C5: 3500 | D5: 10223.04 | E5: 3500 | F5: 0 | G5: 0 | I5: 3850 | K5: 3850 | M5: 3850
A6: VENDAS SHOPEE - VIP MX | C6: 3000 | D6: 11860.57 | E6: 3000 | F6: 15742.89 | G6: 3000 | H6: 33406.21 | I6: 3300 | J6: 38333.32 | K6: 3300 | M6: 3300
A7: RENDIMENTOS | C7: 0 | D7: 0 | E7: 0 | G7: 0 | I7: =G7*0.1+G7 -> 0 | K7: 0 | M7: 0
A10: (-) Despesas do Negócio | C10: =SUM(C11:C23) -> 395348.93 | D10: =SUM(D11:D23) -> 439765.25 | E10: =SUM(E11:E23) -> 343180.71 | F10: =SUM(F11:F23) -> 389391.98 | G10: =SUM(G11:G23) -> 301860.87 | H10: =SUM(H11:H23) -> 464461.03 | I10: =SUM(I11:I23) -> 228299.94 | J10: =SUM(J11:J23) -> 409521.59 | ... Z10: =SUM(Z11:Z23) -> 0
A11: Despesas de pessoal | C11: =1788.08+2195.77+2244.39 -> 6228.24 | D11: =1788.08+2195.77+2244.39+547.99+877.48 -> 7653.71 | E11: =1899+2240.5+1647.2+467.48+791.56 -> 7045.74 | F11: =1788.08+2195.77+1690.53+845.22+499.17 -> 7018.77 | G11: =1899+2240.5+1647.2+467.48+791.56 -> 7045.74 | H11: =2156.17+2195.77+1690.53+531.53+881.63 -> 7455.63 | I11: =1899+2240.5+1647.2+467.48+791.56 -> 7045.74 | J11: =2156.17+3181.6+1690.53+961.58+595.16 -> 8585.04 | K11: =1899+2240.5+1647.2+467.48+791.56 -> 7045.74 | M11: =1899+2240.5+1647.2+467.48+791.56 -> 7045.74
A12: Consultorias e acessorias | C12: =1000+600 -> 1600 | D12: =1000+600 -> 1600 | E12: =1000+600 -> 1600 | F12: =1000+1140 -> 2140 | G12: =1000+600 -> 1600 | H12: =1000+600 -> 1600 | I12: =1000+600 -> 1600 | J12: =1000+640 -> 1640 | K12: =1000+600 -> 1600 | M12: =1000+600 -> 1600
A13: Despesas gerais | C13: 0 | D13: 0 | E13: 0 | F13: 0 | G13: 0 | H13: 0 | I13: 0 | J13: 0 | K13: 0 | L13: 0 | M13: 0 | N13: 0
A14: Tecnologia | C14: 250 | D14: 250 | E14: 250 | F14: 250 | G14: 250 | H14: 250 | I14: 250 | J14: 250 | K14: 250 | M14: 250
A15: Despesas de materia prima | C15: =239024.48+24129.21 -> 263153.69 | D15: 252772.95 | E15: 217067.97 | F15: 228525.11 | G15: 176833.13 | H15: 268703.5 | I15: 91175.7 | J15: 223982.07 | K15: 48922.88 | M15: 21761.12
A16: Despesas de vendas | C16: 2000 | D16: =657.97+697.86 -> 1355.83 | E16: 2000 | F16: 0 | G16: 2000 | H16: =772.85+481.63+508.39 -> 1762.87 | I16: 2000 | J16: =1281.55 -> 1281.55 | K16: 2000 | M16: 2000
A17: Despesas de marketing | C17: 3000 | D17: 0 | E17: 3000 | F17: 0 | G17: 3000 | H17: 0 | I17: 3250 | K17: 3250 | M17: 3250
A18: Impostos Retido de Terceiro | C18: 0 | D18: 0 | E18: 0 | F18: 0 | G18: 0 | I18: 0 | K18: 0 | M18: 0
A19: Impostos | C19: =C4*0.115 -> 29900 | D19: =494.65+28007.24+4855.54 -> 33357.43 | E19: 23000 | F19: =25286.06+1261.89 -> 26547.95 | G19: 23000 | H19: =31526.88+3684.03 -> 35210.91 | I19: 25500 | J19: =37578.42+2450.02 -> 40028.44 | K19: 25500 | M19: 25500
A20: Despesas financeiras | C20: 0 | D20: 0 | E20: 0 | F20: 0 | G20: 0 | I20: 0 | K20: 0 | M20: 0
A21: Taxas plataforma | C21: =(C4+C5+C6)*0.26 -> 69290 | D21: 100405.73 | E21: =(E4+E5+E6)*0.26 -> 69290 | F21: =85892.13 -> 85892.13 | G21: =(G4+G5+G6)*0.26 -> 68380 | H21: 105426.96 | I21: =(I4+I5+I6)*0.26 -> 76219 | J21: 78212.99 | K21: =(K4+K5+K6)*0.26 -> 76219 | M21: =(M4+M5+M6)*0.26 -> 76219
A22: Cancelamentos e Remmbolso | C22: =(C4+C5+C6)*0.05 -> 13325 | D22: 35767.6 | E22: =(E4+E5+E6)*0.05 -> 13325 | F22: =32416.02 -> 32416.02 | G22: =(G4+G5+G6)*0.05 -> 13150 | H22: 37449.16 | I22: =(I4+I5+I6)*0.05 -> 14657.5 | J22: 48939.5 | K22: =(K4+K5+K6)*0.05 -> 14657.5 | M22: =(M4+M5+M6)*0.05 -> 14657.5
A23: Financiamentos | C23: 6602 | D23: 6602 | E23: 6602 | F23: 6602 | G23: 6602 | H23: 6602 | I23: 6602 | J23: 6602 | K23: 6602 | M23: 6602
A24: Resultado | C24: =C3-C10 -> -128848.93 | D24: =D3-D10 -> -4409.78 | E24: =E3-E10 -> -76680.71 | F24: =F3-F10 -> -26198.19 | G24: =G3-G10 -> -38860.87 | H24: =H3-H10 -> -18203.49 | I24: =I3-I10 -> 64850.06 | J24: =J3-J10 -> 136391.74 | ... Z24: =Z3-Z10 -> 0
G41: =6*15 -> 90

Sheet PLANO ORÇAMENTARIO - VIDAL
A1: VIDAL | C1: Previsto | D1: Realizado | E1: Previsto | F1: Realizado | G1: Previsto | H1: Realizado | I1: Previsto | J1: Realizado | K1: Previsto | L1: Realizado | M1: Previsto | N1: Realizado | O1: Previsto | P1: Realizado | Q1: Previsto | R1: Realizado | S1: Previsto | T1: Realizado | U1: Previsto | V1: Realizado | W1: Previsto | X1: Realizado | Y1: Previsto | Z1: Realizado
C2: 46023 | D2: 46023 | E2: 46054 | F2: 46054 | G2: 46082 | H2: 46082 | I2: 46113 | J2: 46113 | K2: 46143 | L2: 46143 | M2: 46174 | N2: 46174 | O2: 46204 | P2: 46204 | Q2: 46235 | R2: 46235 | S2: 46266 | T2: 46266 | U2: 46296 | V2: 46296 | W2: 46327 | X2: 46327 | Y2: 46357 | Z2: 46357
A3: Receita Bruta | C3: =SUM(C4:C7) -> 207000 | D3: =SUM(D4:D7) -> 196570.68 | E3: =SUM(E4:E7) -> 207000 | F3: =SUM(F4:F7) -> 167144.26 | G3: =SUM(G4:G7) -> 207000 | H3: =SUM(H4:H7) -> 229018.47 | I3: =SUM(I4:I7) -> 227700 | J3: =SUM(J4:J7) -> 251047.64 | ... Z3: =SUM(Z4:Z7) -> 0
A4: VENDAS LOJA FISICA | C4: 50000 | D4: 44021.86 | E4: 50000 | F4: 29797.32 | G4: 50000 | H4: 56728.92 | I4: 55000 | J4: 58148.23 | K4: 55000 | M4: 55000 | O4: =M4*0.06+M4 -> 58300
A5: VENDAS MERCADO LIVRE - VIDAL | C5: 155000 | D5: 138853.28 | E5: 155000 | F5: 120539.51 | G5: 155000 | H5: 144159.46 | I5: 170500 | J5: =167726.63+2481.96 -> 170208.59 | K5: 170500 | M5: 170500 | O5: =M5*0.06+M5 -> 180730
A6: VENDAS SHOPEE - VIDAL | C6: 2000 | D6: 13695.54 | E6: 2000 | F6: 16807.43 | G6: 2000 | H6: 28130.09 | I6: 2200 | J6: 22690.82 | K6: 2200 | M6: 2200 | O6: =M6*0.06+M6 -> 2332
A7: RENDIMENTOS | C7: 0 | D7: 0 | E7: 0 | G7: 0 | I7: =G7*0.1+G7 -> 0 | K7: 0 | M7: 0 | O7: =M7*0.06+M7 -> 0
A10: (-) Despesas do Negócio | C10: =SUM(C11:C23) -> 182853.5 | D10: =SUM(D11:D23) -> 71161.33 | E10: =SUM(E11:E23) -> 182853.5 | F10: =SUM(F11:F23) -> 86782.26 | G10: =SUM(G11:G23) -> 182853.5 | H10: =SUM(H11:H23) -> 101713.57 | I10: =SUM(I11:I23) -> 194013.91 | J10: =SUM(J11:J23) -> 135846.61 | ... Z10: =SUM(Z11:Z23) -> 0
A11: Despesas de pessoal | C11: =20000+2240.5+493 -> 22733.5 | D11: =17000+178.31 -> 17178.31 | E11: =20000+2240.5+493 -> 22733.5 | F11: =17000+178.31 -> 17178.31 | G11: =20000+2240.5+493 -> 22733.5 | H11: =17000+178.31+800 -> 17978.31 | I11: =17000+178.31+1098.6 -> 18276.91 | J11: =17000+178.31+1098.6 -> 18276.91 | K11: =17000+178.31+1831 -> 19009.31 | M11: =17000+178.31+1831 -> 19009.31 | O11: =17000+178.31+1831 -> 19009.31
A12: Consultorias e acessorias | C12: 0 | D12: 0 | E12: 0 | F12: 0 | G12: 0 | H12: 0 | I12: 0 | J12: 0 | K12: 0 | L12: 0 | M12: 0 | N12: 0 | O12: 0 | P12: 0
A13: Despesas gerais | C13: =2150+850+250+5000 -> 8250 | D13: =2150+857.07+250+2795.79 -> 6052.86 | E13: =2150+850+250+5000 -> 8250 | F13: =2150+850+250+3000+1000+1822.82 -> 9072.82 | G13: =2150+850+250+5000 -> 8250 | H13: =1100+826.94+250+2844.98 -> 5021.92 | I13: =2150+850+250+5000 -> 8250 | J13: =2100+826.94+250+3393.01+161.39 -> 6731.34 | K13: =2150+850+250+5000 -> 8250 | M13: =2150+850+250+5000 -> 8250 | O13: =2150+850+250+5000 -> 8250
A14: Tecnologia | C14: 200 | D14: 200 | E14: 200 | F14: 200 | G14: 200 | H14: =200+500 -> 700 | I14: =200+250 -> 450 | J14: =200+250+149 -> 599 | K14: 200 | M14: 200 | O14: 200
A15: Despesas de materia prima | C15: 90000 | D15: 0 | E15: 90000 | F15: 3059.34 | G15: 90000 | H15: 10570.07 | I15: 98000 | J15: 30495.45 | K15: 98000 | M15: 98000 | O15: 105000
A16: Despesas de vendas | C16: 0 | D16: 0 | E16: 0 | F16: 0 | G16: 0 | H16: 0 | I16: 0 | J16: 0 | K16: 0 | L16: 0 | M16: 0 | N16: 0 | O16: 0 | P16: 0
A17: Despesas de marketing | C17: 0 | D17: 0 | E17: 0 | F17: 0 | G17: 0 | H17: 440 | I17: 0 | J17: 500 | K17: 0 | L17: 0 | M17: 0 | N17: 0 | O17: 0 | P17: 0
A18: Impostos Retido de Terceiro | C18: 0 | D18: 0 | E18: 0 | G18: 0 | H18: 0 | I18: 0 | K18: 0 | M18: 0 | O18: 0
A19: Impostos | C19: 13000 | D19: 8842.69 | E19: 13000 | F19: =68.72+8852.98 -> 8921.7 | G19: 13000 | H19: 10958.27 | I19: 15500 | J19: 11197.46 | K19: 15500 | M19: 15500 | O19: 18900
A20: Despesas financeiras | C20: 0 | D20: 0 | E20: 0 | G20: 0 | H20: 0 | I20: 0 | K20: 0 | M20: 0 | O20: 0
A21: Taxas plataforma | C21: =(C5+C6)*0.26 -> 40820 | D21: 22834.91 | E21: =(E5+E6)*0.26 -> 40820 | F21: 32636.18 | G21: =(G5+G6)*0.26 -> 40820 | H21: 39540.71 | I21: =(I5+I6)*0.26 -> 44902 | J21: =25220.26+20695.89 -> 45916.15 | K21: =(K5+K6)*0.26 -> 44902 | M21: =(M5+M6)*0.26 -> 44902 | O21: =(O5+O6)*0.26 -> 47596.12
A22: Cancelamentos e Remmbolso | C22: =(C5+C6)*0.05 -> 7850 | D22: 16052.56 | E22: =(E5+E6)*0.05 -> 7850 | F22: 15713.91 | G22: =(G5+G6)*0.05 -> 7850 | H22: 16504.29 | I22: =(I5+I6)*0.05 -> 8635 | J22: =22130.3 -> 22130.3 | K22: =(K5+K6)*0.05 -> 8635 | M22: =(M5+M6)*0.05 -> 8635 | O22: =(O5+O6)*0.05 -> 9153.1
A23: Financiamentos | C23: 0 | D23: 0 | E23: 0 | F23: 0 | G23: 0 | H23: 0 | I23: 0 | J23: 0 | K23: 0 | L23: 0 | M23: 0 | N23: 0 | O23: 0 | P23: 0
A24: Resultado | C24: =C3-C10 -> 24146.5 | D24: =D3-D10 -> 125409.35 | E24: =E3-E10 -> 24146.5 | F24: =F3-F10 -> 80362 | G24: =G3-G10 -> 24146.5 | H24: =H3-H10 -> 127304.9 | I24: =I3-I10 -> 33686.09 | J24: =J3-J10 -> 115201.03 | ... Z24: =Z3-Z10 -> 0

Sheet PLANO ORÇAMENTARIO - V3
A1: V3 | C1: Previsto | D1: Realizado | E1: Previsto | F1: Realizado | G1: Previsto | H1: Realizado | I1: Previsto | J1: Realizado | K1: Previsto | L1: Realizado | M1: Previsto | N1: Realizado | O1: Previsto | P1: Realizado | Q1: Previsto | R1: Realizado | S1: Previsto | T1: Realizado | U1: Previsto | V1: Realizado | W1: Previsto | X1: Realizado | Y1: Previsto | Z1: Realizado
C2: 46023 | D2: 46023 | E2: 46054 | F2: 46054 | G2: 46082 | H2: 46082 | I2: 46113 | J2: 46113 | K2: 46143 | L2: 46143 | M2: 46174 | N2: 46174 | O2: 46204 | P2: 46204 | Q2: 46235 | R2: 46235 | S2: 46266 | T2: 46266 | U2: 46296 | V2: 46296 | W2: 46327 | X2: 46327 | Y2: 46357 | Z2: 46357
A3: Receita Bruta | C3: =SUM(C4:C5) -> 7500 | D3: =SUM(D4:D5) -> 2706 | E3: =SUM(E4:E5) -> 7500 | F3: =SUM(F4:F5) -> 3774.1 | G3: =SUM(G4:G5) -> 7500 | H3: =SUM(H4:H5) -> 3913 | I3: =SUM(I4:I5) -> 3913 | J3: =SUM(J4:J5) -> 3918 | ... Z3: =SUM(Z4:Z5) -> 0
A4: VENDAS MERCADO LIVRE - V3 | C4: 7500 | D4: 2706 | E4: 7500 | F4: =3556.2+217.9 -> 3774.1 | G4: 7500 | H4: 3913 | I4: 3913 | J4: 3918 | K4: 8250 | M4: 8250 | O4: =M4*0.06+M4 -> 8745
A5: RENDIMENTOS | C5: 0 | D5: 0 | E5: 0 | G5: 0 | I5: =G5*0.1+G5 -> 0 | K5: 0 | M5: 0 | O5: =M5*0.06+M5 -> 0 | Q5: 0 | S5: 0 | U5: =S5*0.05+S5 -> 0 | W5: 0 | Y5: 0 | Z5: 0
A8: (-) Despesas do Negócio | C8: =SUM(C9:C21) -> 2250 | D8: =SUM(D9:D21) -> 578 | E8: =SUM(E9:E21) -> 2250 | F8: =SUM(F9:F21) -> 1002.38 | G8: =SUM(G9:G21) -> 2250 | H8: =SUM(H9:H21) -> 1205.54 | I8: =SUM(I9:I21) -> 1173.9 | J8: =SUM(J9:J21) -> 1404.5 | ... Z8: =SUM(Z9:Z21) -> 0
A9: Despesas de pessoal | C9: 0 | D9: 0 | E9: 0 | F9: 0 | G9: 0 | H9: 0 | I9: 0 | J9: 0 | K9: 0 | L9: 0 | M9: 0 | N9: 0 | O9: 0 | P9: 0 | Q9: 0 | R9: 0 | S9: 0 | T9: 0 | U9: 0 | V9: 0 | W9: 0 | X9: 0 | Y9: 0 | Z9: 0
A10: Consultorias e acessorias | C10: 0 | D10: 0 | E10: 0 | F10: 0 | G10: 0 | H10: 0 | I10: 0 | J10: 0 | K10: 0 | L10: 0 | M10: 0 | N10: 0 | O10: 0 | P10: 0 | Q10: 0 | R10: 0 | S10: 0 | T10: 0 | U10: 0 | V10: 0 | W10: 0 | X10: 0 | Y10: 0 | Z10: 0
A11: Despesas gerais | C11: 0 | D11: 0 | E11: 0 | F11: 0 | G11: 0 | H11: 0 | I11: 0 | J11: 0 | K11: 0 | L11: 0 | M11: 0 | N11: 0 | O11: 0 | P11: 0 | Q11: 0 | R11: 0 | S11: 0 | T11: 0 | U11: 0 | V11: 0 | W11: 0 | X11: 0 | Y11: 0 | Z11: 0
A12: Tecnologia | C12: 0 | D12: 0 | E12: 0 | F12: 0 | G12: 0 | H12: 0 | I12: 0 | J12: 0 | K12: 0 | L12: 0 | M12: 0 | N12: 0 | O12: 0 | P12: 0 | Q12: 0 | R12: 0 | S12: 0 | T12: 0 | U12: 0 | V12: 0 | W12: 0 | X12: 0 | Y12: 0 | Z12: 0
A13: Despesas de materia prima | C13: 0 | D13: 0 | E13: 0 | F13: 0 | G13: 0 | H13: 0 | I13: 0 | J13: 0 | K13: 0 | L13: 0 | M13: 0 | N13: 0 | O13: 0 | P13: 0 | Q13: 0 | R13: 0 | S13: 0 | T13: 0 | U13: 0 | V13: 0 | W13: 0 | X13: 0 | Y13: 0 | Z13: 0
A14: Despesas de vendas | C14: 0 | D14: 0 | E14: 0 | F14: 0 | G14: 0 | H14: 0 | I14: 0 | J14: 0 | K14: 0 | L14: 0 | M14: 0 | N14: 0 | O14: 0 | P14: 0 | Q14: 0 | R14: 0 | S14: 0 | T14: 0 | U14: 0 | V14: 0 | W14: 0 | X14: 0 | Y14: 0 | Z14: 0
A15: Despesas de marketing | C15: 0 | D15: 0 | E15: 0 | F15: 0 | G15: 0 | H15: 0 | I15: 0 | J15: 0 | K15: 0 | L15: 0 | M15: 0 | N15: 0 | O15: 0 | P15: 0 | Q15: 0 | R15: 0 | S15: 0 | T15: 0 | U15: 0 | V15: 0 | W15: 0 | X15: 0 | Y15: 0 | Z15: 0
A16: Impostos Retido de Terceiro | C16: 0 | D16: 0 | E16: 0 | F16: 0 | G16: 0 | H16: 0 | I16: 0 | J16: 0 | K16: 0 | L16: 0 | M16: 0 | N16: 0 | O16: 0 | P16: 0 | Q16: 0 | R16: 0 | S16: 0 | T16: 0 | U16: 0 | V16: 0 | W16: 0 | X16: 0 | Y16: 0 | Z16: 0
A17: Impostos | C17: 0 | D17: 0 | E17: 0 | F17: 0 | G17: 0 | H17: 0 | I17: 0 | J17: 0 | K17: 0 | L17: 0 | M17: 0 | N17: 0 | O17: 0 | P17: 0 | Q17: 0 | R17: 0 | S17: 0 | T17: 0 | U17: 0 | V17: 0 | W17: 0 | X17: 0 | Y17: 0 | Z17: 0
A18: Despesas financeiras | C18: 0 | D18: 0 | E18: 0 | F18: 0 | G18: 0 | H18: 0 | I18: 0 | J18: 0 | K18: 0 | L18: 0 | M18: 0 | N18: 0 | O18: 0 | P18: 0 | Q18: 0 | R18: 0 | S18: 0 | T18: 0 | U18: 0 | V18: 0 | W18: 0 | X18: 0 | Y18: 0 | Z18: 0
A19: Taxas plataforma | C19: =C4*0.25 -> 1875 | D19: 578 | E19: =E4*0.25 -> 1875 | F19: 671.91 | G19: =G4*0.25 -> 1875 | H19: 1205.54 | I19: =I4*0.25 -> 978.25 | J19: 1118 | K19: =K4*0.25 -> 2062.5 | L19: 0 | M19: =M4*0.25 -> 2062.5 | N19: 0 | O19: =O4*0.25 -> 2186.25 | P19: 0 | Q19: =Q4*0.25 -> 0 | R19: 0 | S19: =S4*0.25 -> 0 | T19: 0 | U19: =U4*0.25 -> 0 | V19: 0 | W19: =W4*0.25 -> 0 | X19: 0 | Y19: =Y4*0.25 -> 0 | Z19: 0
A20: Cancelamentos e Remmbolso | C20: =C4*0.05 -> 375 | D20: 0 | E20: =E4*0.05 -> 375 | F20: 330.47 | G20: =G4*0.05 -> 375 | H20: 0 | I20: =I4*0.05 -> 195.65 | J20: 286.5 | K20: =K4*0.05 -> 412.5 | L20: 0 | M20: =M4*0.05 -> 412.5 | N20: 0 | O20: =O4*0.05 -> 437.25 | P20: 0 | Q20: =Q4*0.05 -> 0 | R20: 0 | S20: =S4*0.05 -> 0 | T20: 0 | U20: =U4*0.05 -> 0 | V20: 0 | W20: =W4*0.05 -> 0 | X20: 0 | Y20: =Y4*0.05 -> 0 | Z20: 0
A21: Financiamentos | C21: 0 | D21: 0 | E21: 0 | F21: 0 | G21: 0 | H21: 0 | I21: 0 | J21: 0 | K21: 0 | L21: 0 | M21: 0 | N21: 0 | O21: 0 | P21: 0 | Q21: 0 | R21: 0 | S21: 0 | T21: 0 | U21: 0 | V21: 0 | W21: 0 | X21: 0 | Y21: 0 | Z21: 0
A22: Resultado | C22: =C3-C8 -> 5250 | D22: =D3-D8 -> 2128 | E22: =E3-E8 -> 5250 | F22: =F3-F8 -> 2771.72 | G22: =G3-G8 -> 5250 | H22: =H3-H8 -> 2707.46 | I22: =I3-I8 -> 2739.1 | J22: =J3-J8 -> 2513.5 | ... Z22: =Z3-Z8 -> 0

Sheet Planilha1
A1: VIP MX | C1: Previsto | D1: Realizado | E1: Previsto | F1: Realizado | G1: Previsto | H1: Realizado | I1: Previsto | J1: Realizado | K1: Previsto | L1: Realizado | M1: Previsto | N1: Realizado | O1: Previsto | P1: Realizado | Q1: Previsto | R1: Realizado | S1: Previsto | T1: Realizado | U1: Previsto | V1: Realizado | W1: Previsto | X1: Realizado | Y1: Previsto | Z1: Realizado
C2: 46023 | D2: 46023 | E2: 46054 | F2: 46054 | G2: 46082 | H2: 46082 | I2: 46113 | J2: 46113 | K2: 46143 | L2: 46143 | M2: 46174 | N2: 46174 | O2: 46204 | P2: 46204 | Q2: 46235 | R2: 46235 | S2: 46266 | T2: 46266 | U2: 46296 | V2: 46296 | W2: 46327 | X2: 46327 | Y2: 46357 | Z2: 46357
A3: Receita Bruta | C3: =SUM(C4:C7) -> 266500 | D3: =SUM(D4:D7) -> 435355.47 | E3: =SUM(E4:E7) -> 266500 | F3: =SUM(F4:F7) -> 363193.79 | G3: =SUM(G4:G7) -> 263000 | H3: =SUM(H4:H7) -> 446257.54 | I3: =SUM(I4:I7) -> 293150 | J3: =SUM(J4:J7) -> 545913.33 | ... Z3: =SUM(Z4:Z7) -> 0
A4: VENDAS MERCADO LIVRE - VIP MX | C4: 260000 | D4: 413271.86 | E4: 260000 | F4: 347450.9 | G4: 260000 | H4: 412851.33 | I4: 286000 | J4: =507580.01 -> 507580.01 | K4: 286000 | M4: 286000 | O4: =M4*0.06+M4 -> 303160 | Q4: 303160 | S4: 303160 | U4: =S4*0.05+S4 -> 318318 | W4: 318318 | Y4: 318318 | Z4: 0
A5: VENDAS AMAZON - VIP MX | C5: 3500 | D5: 10223.04 | E5: 3500 | F5: 0 | G5: 0 | I5: 3850 | K5: 3850 | M5: 3850 | O5: =M5*0.06+M5 -> 4081 | Q5: 4081 | S5: 4081 | U5: =S5*0.05+S5 -> 4285.05 | W5: 4285.05 | Y5: 4285.05 | Z5: 0
A6: VENDAS SHOPEE - VIP MX | C6: 3000 | D6: 11860.57 | E6: 3000 | F6: 15742.89 | G6: 3000 | H6: 33406.21 | I6: 3300 | J6: 38333.32 | K6: 3300 | M6: 3300 | O6: =M6*0.06+M6 -> 3498 | Q6: 3498 | S6: 3498 | U6: =S6*0.05+S6 -> 3672.9 | W6: 3672.9 | Y6: 3672.9 | Z6: 0
A7: RENDIMENTOS | C7: 0 | D7: 0 | E7: 0 | G7: 0 | I7: =G7*0.1+G7 -> 0 | K7: 0 | M7: 0 | O7: =M7*0.06+M7 -> 0 | Q7: 0 | S7: 0 | U7: =S7*0.05+S7 -> 0 | W7: 0 | Y7: 0 | Z7: 0
A10: (-) Despesas do Negócio | C10: =SUM(C11:C23) -> 395348.93 | D10: =SUM(D11:D23) -> 439765.25 | E10: =SUM(E11:E23) -> 343180.71 | F10: =SUM(F11:F23) -> 389391.98 | G10: =SUM(G11:G23) -> 301860.87 | H10: =SUM(H11:H23) -> 464461.03 | I10: =SUM(I11:I23) -> 228299.94 | J10: =SUM(J11:J23) -> 409521.59 | ... Z10: =SUM(Z11:Z23) -> 0
A11: Despesas de pessoal | C11: =1788.08+2195.77+2244.39 -> 6228.24 | D11: =1788.08+2195.77+2244.39+547.99+877.48 -> 7653.71 | E11: =1899+2240.5+1647.2+467.48+791.56 -> 7045.74 | F11: =1788.08+2195.77+1690.53+845.22+499.17 -> 7018.77 | G11: =1899+2240.5+1647.2+467.48+791.56 -> 7045.74 | H11: =2156.17+2195.77+1690.53+531.53+881.63 -> 7455.63 | I11: =1899+2240.5+1647.2+467.48+791.56 -> 7045.74 | J11: =2156.17+3181.6+1690.53+961.58+595.16 -> 8585.04 | K11: =1899+2240.5+1647.2+467.48+791.56 -> 7045.74 | M11: =1899+2240.5+1647.2+467.48+791.56 -> 7045.74 | O11: =1899+2240.5+1647.2+467.48+791.56 -> 7045.74 | Q11: =1899+2240.5+1647.2+467.48+791.56 -> 7045.74 | S11: =1899+2240.5+1647.2+467.48+791.56 -> 7045.74 | U11: =1899+2240.5+1647.2+467.48+791.56 -> 7045.74 | W11: =1899+2240.5+1647.2+467.48+791.56 -> 7045.74 | Y11: =1899+2240.5+1647.2+467.48+791.56 -> 7045.74 | Z11: 0
A12: Consultorias e acessorias | C12: =1000+600 -> 1600 | D12: =1000+600 -> 1600 | E12: =1000+600 -> 1600 | F12: =1000+1140 -> 2140 | G12: =1000+600 -> 1600 | H12: =1000+600 -> 1600 | I12: =1000+600 -> 1600 | J12: =1000+640 -> 1640 | K12: =1000+600 -> 1600 | M12: =1000+600 -> 1600 | O12: =1000+600 -> 1600 | Q12: =1000+600 -> 1600 | S12: =1000+600 -> 1600 | U12: =1000+600 -> 1600 | W12: =1000+600 -> 1600 | Y12: =1000+600 -> 1600 | Z12: 0
A13: Despesas gerais | C13: 0 | D13: 0 | E13: 0 | F13: 0 | G13: 0 | H13: 0 | I13: 0 | J13: 0 | K13: 0 | L13: 0 | M13: 0 | N13: 0 | O13: 0 | P13: 0 | Q13: 0 | R13: 0 | S13: 0 | T13: 0 | U13: 0 | V13: 0 | W13: 0 | X13: 0 | Y13: 0 | Z13: 0
A14: Tecnologia | C14: 250 | D14: 250 | E14: 250 | F14: 250 | G14: 250 | H14: 250 | I14: 250 | J14: 250 | K14: 250 | M14: 250 | O14: 250 | Q14: 250 | S14: 250 | U14: 250 | W14: 250 | Y14: 250 | Z14: 0
A15: Despesas de materia prima | C15: =239024.48+24129.21 -> 263153.69 | D15: 252772.95 | E15: 217067.97 | F15: 228525.11 | G15: 176833.13 | H15: 268703.5 | I15: 91175.7 | J15: 223982.07 | K15: 48922.88 | M15: 21761.12 | O15: 5550.03 | Q15: 152000 | S15: 152000 | U15: 162500 | W15: 162500 | Y15: 162500 | Z15: 0
A16: Despesas de vendas | C16: 2000 | D16: =657.97+697.86 -> 1355.83 | E16: 2000 | F16: 0 | G16: 2000 | H16: =772.85+481.63+508.39 -> 1762.87 | I16: 2000 | J16: =1281.55 -> 1281.55 | K16: 2000 | M16: 2000 | O16: 2000 | Q16: 2000 | S16: 2000 | U16: 2000 | W16: 2000 | Y16: 2000 | Z16: 0
A17: Despesas de marketing | C17: 3000 | D17: 0 | E17: 3000 | F17: 0 | G17: 3000 | H17: 0 | I17: 3250 | K17: 3250 | M17: 3250 | O17: 3500 | Q17: 3500 | S17: 3500 | U17: 4000 | W17: 4000 | Y17: 4000 | Z17: 0
A18: Impostos Retido de Terceiro | C18: 0 | D18: 0 | E18: 0 | F18: 0 | G18: 0 | I18: 0 | K18: 0 | M18: 0 | O18: 0 | Q18: 0 | S18: 0 | U18: 0 | W18: 0 | Y18: 0 | Z18: 0
A19: Impostos | C19: =C4*0.115 -> 29900 | D19: =494.65+28007.24+4855.54 -> 33357.43 | E19: 23000 | F19: =25286.06+1261.89 -> 26547.95 | G19: 23000 | H19: =31526.88+3684.03 -> 35210.91 | I19: 25500 | J19: =37578.42+2450.02 -> 40028.44 | K19: 25500 | M19: 25500 | O19: 28500 | Q19: 28500 | S19: 28500 | U19: 32000 | W19: 32000 | Y19: 32000 | Z19: 0
A20: Despesas financeiras | C20: 0 | D20: 0 | E20: 0 | F20: 0 | G20: 0 | I20: 0 | K20: 0 | M20: 0 | O20: 0 | Q20: 0 | S20: 0 | U20: 0 | W20: 0 | Y20: 0 | Z20: 0
A21: Taxas plataforma | C21: =(C4+C5+C6)*0.26 -> 69290 | D21: 100405.73 | E21: =(E4+E5+E6)*0.26 -> 69290 | F21: =85892.13 -> 85892.13 | G21: =(G4+G5+G6)*0.26 -> 68380 | H21: 105426.96 | I21: =(I4+I5+I6)*0.26 -> 76219 | J21: 78212.99 | K21: =(K4+K5+K6)*0.26 -> 76219 | M21: =(M4+M5+M6)*0.26 -> 76219 | O21: =(O4+O5+O6)*0.26 -> 80792.14 | Q21: =(Q4+Q5+Q6)*0.26 -> 80792.14 | S21: =(S4+S5+S6)*0.26 -> 80792.14 | U21: =(U4+U5+U6)*0.26 -> 84831.747 | W21: =(W4+W5+W6)*0.26 -> 84831.747 | Y21: =(Y4+Y5+Y6)*0.26 -> 84831.747 | Z21: 0
A22: Cancelamentos e Remmbolso | C22: =(C4+C5+C6)*0.05 -> 13325 | D22: 35767.6 | E22: =(E4+E5+E6)*0.05 -> 13325 | F22: =32416.02 -> 32416.02 | G22: =(G4+G5+G6)*0.05 -> 13150 | H22: 37449.16 | I22: =(I4+I5+I6)*0.05 -> 14657.5 | J22: 48939.5 | K22: =(K4+K5+K6)*0.05 -> 14657.5 | M22: =(M4+M5+M6)*0.05 -> 14657.5 | O22: =(O4+O5+O6)*0.05 -> 15536.95 | Q22: =(Q4+Q5+Q6)*0.05 -> 15536.95 | S22: =(S4+S5+S6)*0.05 -> 15536.95 | U22: =(U4+U5+U6)*0.05 -> 16313.798 | W22: =(W4+W5+W6)*0.05 -> 16313.798 | Y22: =(Y4+Y5+Y6)*0.05 -> 16313.798 | Z22: 0
A23: Financiamentos | C23: 6602 | D23: 6602 | E23: 6602 | F23: 6602 | G23: 6602 | H23: 6602 | I23: 6602 | J23: 6602 | K23: 6602 | M23: 6602 | O23: 6602 | Q23: 6602 | S23: 6602 | U23: 6602 | W23: 6602 | Y23: 6602 | Z23: 0
A24: Resultado | C24: =C3-C10 -> -128848.93 | D24: =D3-D10 -> -4409.78 | E24: =E3-E10 -> -76680.71 | F24: =F3-F10 -> -26198.19 | G24: =G3-G10 -> -38860.87 | H24: =H3-H10 -> -18203.49 | I24: =I3-I10 -> 64850.06 | J24: =J3-J10 -> 136391.74 | ... Z24: =Z3-Z10 -> 0
A27: VIDAL | C27: Previsto | D27: Realizado | E27: Previsto | F27: Realizado | G27: Previsto | H27: Realizado | I27: Previsto | J27: Realizado | K27: Previsto | L27: Realizado | M27: Previsto | N27: Realizado | O27: Previsto | P27: Realizado | Q27: Previsto | R27: Realizado | S27: Previsto | T27: Realizado | U27: Previsto | V27: Realizado | W27: Previsto | X27: Realizado | Y27: Previsto | Z27: Realizado
C28: 46023 | D28: 46023 | E28: 46054 | F28: 46054 | G28: 46082 | H28: 46082 | I28: 46113 | J28: 46113 | K28: 46143 | L28: 46143 | M28: 46174 | N28: 46174 | O28: 46204 | P28: 46204 | Q28: 46235 | R28: 46235 | S28: 46266 | T28: 46266 | U28: 46296 | V28: 46296 | W28: 46327 | X28: 46327 | Y28: 46357 | Z28: 46357
A29: Receita Bruta | C29: =SUM(C30:C33) -> 207000 | D29: =SUM(D30:D33) -> 196570.68 | E29: =SUM(E30:E33) -> 207000 | F29: =SUM(F30:F33) -> 167144.26 | G29: =SUM(G30:G33) -> 207000 | H29: =SUM(H30:H33) -> 229018.47 | I29: =SUM(I30:I33) -> 227700 | J29: =SUM(J30:J33) -> 251047.64 | ... Z29: =SUM(Z30:Z33) -> 0
A30: VENDAS LOJA FISICA | C30: 50000 | D30: 44021.86 | E30: 50000 | F30: 29797.32 | G30: 50000 | H30: 56728.92 | I30: 55000 | J30: 58148.23 | K30: 55000 | M30: 55000 | O30: =M30*0.06+M30 -> 58300 | Q30: 58300 | S30: 58300 | U30: =S30*0.05+S30 -> 61215 | W30: 61215 | Y30: 61215 | Z30: 0
A31: VENDAS MERCADO LIVRE - VIDAL | C31: 155000 | D31: 138853.28 | E31: 155000 | F31: 120539.51 | G31: 155000 | H31: 144159.46 | I31: 170500 | J31: =167726.63+2481.96 -> 170208.59 | K31: 170500 | M31: 170500 | O31: =M31*0.06+M31 -> 180730 | Q31: 180730 | S31: 180730 | U31: =S31*0.05+S31 -> 189766.5 | W31: 189766.5 | Y31: 189766.5 | Z31: 0
A32: VENDAS SHOPEE - VIDAL | C32: 2000 | D32: 13695.54 | E32: 2000 | F32: 16807.43 | G32: 2000 | H32: 28130.09 | I32: 2200 | J32: 22690.82 | K32: 2200 | M32: 2200 | O32: =M32*0.06+M32 -> 2332 | Q32: 2332 | S32: 2332 | U32: =S32*0.05+S32 -> 2448.6 | W32: 2448.6 | Y32: 2448.6 | Z32: 0
A33: RENDIMENTOS | C33: 0 | D33: 0 | E33: 0 | G33: 0 | I33: =G33*0.1+G33 -> 0 | K33: 0 | M33: 0 | O33: =M33*0.06+M33 -> 0 | Q33: 0 | S33: 0 | U33: =S33*0.05+S33 -> 0 | W33: 0 | Y33: 0 | Z33: 0
A36: (-) Despesas do Negócio | C36: =SUM(C37:C49) -> 182853.5 | D36: =SUM(D37:D49) -> 71161.33 | E36: =SUM(E37:E49) -> 182853.5 | F36: =SUM(F37:F49) -> 86782.26 | G36: =SUM(G37:G49) -> 182853.5 | H36: =SUM(H37:H49) -> 101713.57 | I36: =SUM(I37:I49) -> 194013.91 | J36: =SUM(J37:J49) -> 135846.61 | ... Z36: =SUM(Z37:Z49) -> 0
A37: Despesas de pessoal | C37: =20000+2240.5+493 -> 22733.5 | D37: =17000+178.31 -> 17178.31 | E37: =20000+2240.5+493 -> 22733.5 | F37: =17000+178.31 -> 17178.31 | G37: =20000+2240.5+493 -> 22733.5 | H37: =17000+178.31+800 -> 17978.31 | I37: =17000+178.31+1098.6 -> 18276.91 | J37: =17000+178.31+1098.6 -> 18276.91 | K37: =17000+178.31+1831 -> 19009.31 | M37: =17000+178.31+1831 -> 19009.31 | O37: =17000+178.31+1831 -> 19009.31 | Q37: =17000+178.31+1831 -> 19009.31 | S37: =17000+178.31+1831 -> 19009.31 | U37: =17000+178.31+1831 -> 19009.31 | W37: =17000+178.31+1831 -> 19009.31 | Y37: =17000+178.31+1831 -> 19009.31 | Z37: 0
A38: Consultorias e acessorias | C38: 0 | D38: 0 | E38: 0 | F38: 0 | G38: 0 | H38: 0 | I38: 0 | J38: 0 | K38: 0 | L38: 0 | M38: 0 | N38: 0 | O38: 0 | P38: 0 | Q38: 0 | R38: 0 | S38: 0 | T38: 0 | U38: 0 | V38: 0 | W38: 0 | X38: 0 | Y38: 0 | Z38: 0
A39: Despesas gerais | C39: =2150+850+250+5000 -> 8250 | D39: =2150+857.07+250+2795.79 -> 6052.86 | E39: =2150+850+250+5000 -> 8250 | F39: =2150+850+250+3000+1000+1822.82 -> 9072.82 | G39: =2150+850+250+5000 -> 8250 | H39: =1100+826.94+250+2844.98 -> 5021.92 | I39: =2150+850+250+5000 -> 8250 | J39: =2100+826.94+250+3393.01+161.39 -> 6731.34 | K39: =2150+850+250+5000 -> 8250 | M39: =2150+850+250+5000 -> 8250 | O39: =2150+850+250+5000 -> 8250 | Q39: =2150+850+250+5000 -> 8250 | S39: =2150+850+250+5000 -> 8250 | U39: =2150+850+250+5000 -> 8250 | W39: =2150+850+250+5000 -> 8250 | Y39: =2150+850+250+5000 -> 8250 | Z39: 0
A40: Tecnologia | C40: 200 | D40: 200 | E40: 200 | F40: 200 | G40: 200 | H40: =200+500 -> 700 | I40: =200+250 -> 450 | J40: =200+250+149 -> 599 | K40: 200 | M40: 200 | O40: 200 | Q40: 200 | S40: 200 | U40: 200 | W40: 200 | Y40: 200 | Z40: 0
A41: Despesas de materia prima | C41: 90000 | D41: 0 | E41: 90000 | F41: 3059.34 | G41: 90000 | H41: 10570.07 | I41: 98000 | J41: 30495.45 | K41: 98000 | M41: 98000 | O41: 105000 | Q41: 105000 | S41: 105000 | U41: 113500 | W41: 113500 | Y41: 113500 | Z41: 0
A42: Despesas de vendas | C42: 0 | D42: 0 | E42: 0 | F42: 0 | G42: 0 | H42: 0 | I42: 0 | J42: 0 | K42: 0 | L42: 0 | M42: 0 | N42: 0 | O42: 0 | P42: 0 | Q42: 0 | R42: 0 | S42: 0 | T42: 0 | U42: 0 | V42: 0 | W42: 0 | X42: 0 | Y42: 0 | Z42: 0
A43: Despesas de marketing | C43: 0 | D43: 0 | E43: 0 | F43: 0 | G43: 0 | H43: 440 | I43: 0 | J43: 500 | K43: 0 | L43: 0 | M43: 0 | N43: 0 | O43: 0 | P43: 0 | Q43: 0 | R43: 0 | S43: 0 | T43: 0 | U43: 0 | V43: 0 | W43: 0 | X43: 0 | Y43: 0 | Z43: 0
A44: Impostos Retido de Terceiro | C44: 0 | D44: 0 | E44: 0 | G44: 0 | H44: 0 | I44: 0 | K44: 0 | M44: 0 | O44: 0 | Q44: 0 | S44: 0 | U44: 0 | W44: 0 | Y44: 0 | Z44: 0
A45: Impostos | C45: 13000 | D45: 8842.69 | E45: 13000 | F45: =68.72+8852.98 -> 8921.7 | G45: 13000 | H45: 10958.27 | I45: 15500 | J45: 11197.46 | K45: 15500 | M45: 15500 | O45: 18900 | Q45: 18900 | S45: 18900 | U45: 23000 | W45: 23000 | Y45: 23000 | Z45: 0
A46: Despesas financeiras | C46: 0 | D46: 0 | E46: 0 | G46: 0 | H46: 0 | I46: 0 | K46: 0 | M46: 0 | O46: 0 | Q46: 0 | S46: 0 | U46: 0 | W46: 0 | Y46: 0 | Z46: 0
...

Sheet Fluxo De caixa - VIP
B1: JANEIRO-26
B2: DATA
C3: Entradas Realizadas | D3: Resgate apl | E3: Aporte Propietario | F3: Despesas realizadas | G3: Aplicação | H3: Shareholder Remuneration | I3: Saldo do dia
I4: 350000
B5: 46023 | C5: 0 | D5: 0 | E5: 0 | F5: 0 | G5: 0 | H5: 0 | I5: =+I4+C5+E5+G5+H5+F5+D5 -> 350000
B6: 46024 | C6: 0 | D6: 0 | E6: 0 | F6: 0 | G6: 0 | H6: 0 | I6: =+I5+C6+E6+G6+H6+F6+D6 -> 350000
B7: 46025 | C7: 0 | D7: 0 | E7: 0 | F7: 0 | G7: 0 | H7: 0 | I7: =+I6+C7+E7+G7+H7+F7+D7 -> 350000
B8: 46026 | C8: 0 | D8: 0 | E8: 0 | F8: 0 | G8: 0 | H8: 0 | I8: =+I7+C8+E8+G8+H8+F8+D8 -> 350000
B9: 46027 | C9: 0 | D9: 0 | E9: 0 | F9: 0 | G9: 0 | H9: 0 | I9: =+I8+C9+E9+G9+H9+F9+D9 -> 350000
B10: 46028 | C10: 0 | D10: 0 | E10: 0 | F10: 0 | G10: 0 | H10: 0 | I10: =+I9+C10+E10+G10+H10+F10+D10 -> 350000
B11: 46029 | C11: 0 | D11: 0 | E11: 0 | F11: 0 | G11: 0 | H11: 0 | I11: =+I10+C11+E11+G11+H11+F11+D11 -> 350000
B12: 46030 | C12: 0 | D12: 0 | E12: 0 | F12: 0 | G12: 0 | H12: 0 | I12: =+I11+C12+E12+G12+H12+F12+D12 -> 350000
B13: 46031 | C13: 0 | D13: 0 | E13: 0 | F13: 0 | G13: 0 | H13: 0 | I13: =+I12+C13+E13+G13+H13+F13+D13 -> 350000
B14: 46032 | C14: 0 | D14: 0 | E14: 0 | F14: 0 | G14: 0 | H14: 0 | I14: =+I13+C14+E14+G14+H14+F14+D14 -> 350000
B15: 46033 | C15: 0 | D15: 0 | E15: 0 | F15: 0 | G15: 0 | H15: 0 | I15: =+I14+C15+E15+G15+H15+F15+D15 -> 350000
B16: 46034 | C16: 0 | D16: 0 | E16: 0 | F16: 0 | G16: 0 | H16: 0 | I16: =+I15+C16+E16+G16+H16+F16+D16 -> 350000
... B35: 46053 | C35: 0 | D35: 0 | E35: 0 | F35: 0 | G35: 0 | H35: 0 | I35: =+I34+C35+E35+G35+H35+F35+D35 -> 350000
B36: TOTAL | C36: =SUM(C5:C35) -> 0 | E36: =SUM(E5:E35) -> 0 | F36: =SUM(F5:F35) -> 0 | G36: =SUM(G5:G35) -> 0 | H36: =SUM(H5:H35) -> 0
B38: Fevereiro-26
B39: DATA
C40: Entradas Realizadas | D40: Resgate apl | E40: Aporte Propietario | F40: Despesas realizadas | G40: Aplicação | H40: Shareholder Remuneration | I40: Saldo do dia
I41: 200000
B42: 46054 | C42: 0 | D42: 0 | E42: 0 | F42: 0 | G42: 0 | H42: 0 | I42: =+I41+C42+E42+G42+H42+F42+D42 -> 200000
B43: 46055 | C43: 0 | D43: 0 | E43: 0 | F43: 0 | G43: 0 | H43: 0 | I43: =+I42+C43+E43+G43+H43+F43+D43 -> 200000
B44: 46056 | C44: 0 | D44: 0 | E44: 0 | F44: 0 | G44: 0 | H44: 0 | I44: =+I43+C44+E44+G44+H44+F44+D44 -> 200000
B45: 46057 | C45: 0 | D45: 0 | E45: 0 | F45: 0 | G45: 0 | H45: 0 | I45: =+I44+C45+E45+G45+H45+F45+D45 -> 200000
B46: 46058 | C46: 0 | D46: 0 | E46: 0 | F46: 0 | G46: 0 | H46: 0 | I46: =+I45+C46+E46+G46+H46+F46+D46 -> 200000
B47: 46059 | C47: 0 | D47: 0 | E47: 0 | F47: 0 | G47: 0 | H47: 0 | I47: =+I46+C47+E47+G47+H47+F47+D47 -> 200000
B48: 46060 | C48: 0 | D48: 0 | E48: 0 | F48: -10062.67 | G48: 0 | H48: 0 | I48: =+I47+C48+E48+G48+H48+F48+D48 -> 189937.33
B49: 46061 | C49: 0 | D49: 0 | E49: 0 | F49: -377.95 | G49: 0 | H49: 0 | I49: =+I48+C49+E49+G49+H49+F49+D49 -> 189559.38
B50: 46062 | C50: 0 | D50: 0 | E50: 0 | F50: -7572.81 | G50: 0 | H50: 0 | I50: =+I49+C50+E50+G50+H50+F50+D50 -> 181986.57
B51: 46063 | C51: 0 | D51: 0 | E51: 0 | F51: -11377.46 | G51: 0 | H51: 0 | I51: =+I50+C51+E51+G51+H51+F51+D51 -> 170609.11
B52: 46064 | C52: 0 | D52: 0 | E52: 0 | F52: -5179.26 | G52: 0 | H52: 0 | I52: =+I51+C52+E52+G52+H52+F52+D52 -> 165429.85
B53: 46065 | C53: 0 | D53: 0 | E53: 0 | F53: -13917.42 | G53: 0 | H53: 0 | I53: =+I52+C53+E53+G53+H53+F53+D53 -> 151512.43
... B60: 46072 | C60: 0 | D60: 0 | E60: 0 | F60: -3905.48 | G60: 0 | H60: 0 | I60: =+I59+C60+E60+G60+H60+F60+D60 -> 90959.14
B61: 46073 | C61: 0 | D61: 0 | E61: 0 | F61: =-(1973+450+40000+8031.05) -> -50454.05 | G61: 0 | H61: 0 | I61: =+I60+C61+E61+G61+H61+F61+D61 -> 40505.09
B62: 46074 | C62: 0 | D62: 0 | E62: 0 | F62: -2198.11 | G62: 0 | H62: 0 | I62: =+I61+C62+E62+G62+H62+F62+D62 -> 38306.98
B63: 46075 | C63: 0 | D63: 0 | E63: 0 | F63: -3304.59 | G63: 0 | H63: 0 | I63: =+I62+C63+E63+G63+H63+F63+D63 -> 35002.39
B64: 46076 | C64: 0 | D64: 0 | E64: 0 | F64: -3678.01 | G64: 0 | H64: 0 | I64: =+I63+C64+E64+G64+H64+F64+D64 -> 31324.38
B65: 46077 | C65: 0 | D65: 0 | E65: 0 | F65: -14281.68 | G65: 0 | H65: 0 | I65: =+I64+C65+E65+G65+H65+F65+D65 -> 17042.7
...

Sheet Fluxo De caixa - VIDAL
B1: JANEIRO-26
B2: DATA
C3: Entradas Realizadas | D3: Resgate apl | E3: Aporte Propietario | F3: Despesas realizadas | G3: Aplicação | H3: Shareholder Remuneration | I3: Saldo do dia
I4: 0
B5: 46023 | C5: 0 | D5: 0 | E5: 0 | F5: -13355.79 | G5: 0 | H5: 0 | I5: =+I4+C5+E5+G5+H5+F5+D5 -> -13355.79
B6: 46024 | C6: 0 | D6: 0 | E6: 0 | F6: -7771.32 | G6: 0 | H6: 0 | I6: =+I5+C6+E6+G6+H6+F6+D6 -> -21127.11
B7: 46025 | C7: 0 | D7: 0 | E7: 0 | F7: -2941.69 | G7: 0 | H7: 0 | I7: =+I6+C7+E7+G7+H7+F7+D7 -> -24068.8
B8: 46026 | C8: 0 | D8: 0 | E8: 0 | F8: -2103.31 | G8: 0 | H8: 0 | I8: =+I7+C8+E8+G8+H8+F8+D8 -> -26172.11
B9: 46027 | C9: 0 | D9: 0 | E9: 0 | F9: =-(9779+17000+2000+3533.7) -> -32312.7 | G9: 0 | H9: 0 | I9: =+I8+C9+E9+G9+H9+F9+D9 -> -58484.81
B10: 46028 | C10: 0 | D10: 0 | E10: 0 | F10: -20097.43 | G10: 0 | H10: 0 | I10: =+I9+C10+E10+G10+H10+F10+D10 -> -78582.24
B11: 46029 | C11: 0 | D11: 0 | E11: 0 | F11: -10346.24 | G11: 0 | H11: 0 | I11: =+I10+C11+E11+G11+H11+F11+D11 -> -88928.48
B12: 46030 | C12: 0 | D12: 0 | E12: 0 | F12: -13283.89 | G12: 0 | H12: 0 | I12: =+I11+C12+E12+G12+H12+F12+D12 -> -102212.37
B13: 46031 | C13: 0 | D13: 0 | E13: 0 | F13: =-(2150+850+250+5000+3000+6840.31) -> -18090.31 | G13: 0 | H13: 0 | I13: =+I12+C13+E13+G13+H13+F13+D13 -> -120302.68
B14: 46032 | C14: 0 | D14: 0 | E14: 0 | F14: -8358.27 | G14: 0 | H14: 0 | I14: =+I13+C14+E14+G14+H14+F14+D14 -> -128660.95
B15: 46033 | C15: 0 | D15: 0 | E15: 0 | F15: -7281.7 | G15: 0 | H15: 0 | I15: =+I14+C15+E15+G15+H15+F15+D15 -> -135942.65
B16: 46034 | C16: 0 | D16: 0 | E16: 0 | F16: -4822.69 | G16: 0 | H16: 0 | I16: =+I15+C16+E16+G16+H16+F16+D16 -> -140765.34
B17: 46035 | C17: 0 | D17: 0 | E17: 0 | F17: -12056.85 | G17: 0 | H17: 0 | I17: =+I16+C17+E17+G17+H17+F17+D17 -> -152822.19
B18: 46036 | C18: 0 | D18: 0 | E18: 0 | F18: -1953.24 | G18: 0 | H18: 0 | I18: =+I17+C18+E18+G18+H18+F18+D18 -> -154775.43
B19: 46037 | C19: 0 | D19: 0 | E19: 0 | F19: =-(6602+4683.06) -> -11285.06 | G19: 0 | H19: 0 | I19: =+I18+C19+E19+G19+H19+F19+D19 -> -166060.49
B20: 46038 | C20: 0 | D20: 0 | E20: 0 | F20: -9768.98 | G20: 0 | H20: 0 | I20: =+I19+C20+E20+G20+H20+F20+D20 -> -175829.47
B21: 46039 | C21: 0 | D21: 0 | E21: 0 | F21: -7181.73 | G21: 0 | H21: 0 | I21: =+I20+C21+E21+G21+H21+F21+D21 -> -183011.2
B22: 46040 | C22: 0 | D22: 0 | E22: 0 | F22: -4401.47 | G22: 0 | H22: 0 | I22: =+I21+C22+E22+G22+H22+F22+D22 -> -187412.67
B23: 46041 | C23: 0 | D23: 0 | E23: 0 | F23: -18370.24 | G23: 0 | H23: 0 | I23: =+I22+C23+E23+G23+H23+F23+D23 -> -205782.91
B24: 46042 | C24: 0 | D24: 0 | E24: 0 | F24: =-(1973+450+40000+7117.18) -> -49540.18 | G24: 0 | H24: 0 | I24: =+I23+C24+E24+G24+H24+F24+D24 -> -255323.09
B25: 46043 | C25: 0 | D25: 0 | E25: 0 | F25: -8604.53 | G25: 0 | H25: 0 | I25: =+I24+C25+E25+G25+H25+F25+D25 -> -263927.62
B26: 46044 | C26: 0 | D26: 0 | E26: 0 | F26: -3392.47 | G26: 0 | H26: 0 | I26: =+I25+C26+E26+G26+H26+F26+D26 -> -267320.09
B27: 46045 | C27: 0 | D27: 0 | E27: 0 | F27: -5848.52 | G27: 0 | H27: 0 | I27: =+I26+C27+E27+G27+H27+F27+D27 -> -273168.61
B28: 46046 | C28: 0 | D28: 0 | E28: 0 | F28: -3958.05 | G28: 0 | H28: 0 | I28: =+I27+C28+E28+G28+H28+F28+D28 -> -277126.66
B29: 46047 | C29: 0 | D29: 0 | E29: 0 | F29: -6206.49 | G29: 0 | H29: 0 | I29: =+I28+C29+E29+G29+H29+F29+D29 -> -283333.15
B30: 46048 | C30: 0 | D30: 0 | E30: 0 | F30: -10448.97 | G30: 0 | H30: 0 | I30: =+I29+C30+E30+G30+H30+F30+D30 -> -293782.12
B31: 46049 | C31: 0 | D31: 0 | E31: 0 | F31: -4945.06 | G31: 0 | H31: 0 | I31: =+I30+C31+E31+G31+H31+F31+D31 -> -298727.18
B32: 46050 | C32: 0 | D32: 0 | E32: 0 | F32: -5272.06 | G32: 0 | H32: 0 | I32: =+I31+C32+E32+G32+H32+F32+D32 -> -303999.24
B33: 46051 | C33: 0 | D33: 0 | E33: 0 | F33: -5055.84 | G33: 0 | H33: 0 | I33: =+I32+C33+E33+G33+H33+F33+D33 -> -309055.08
B34: 46052 | C34: 0 | D34: 0 | E34: 0 | F34: =-(1000+4915.13) -> -5915.13 | G34: 0 | H34: 0 | I34: =+I33+C34+E34+G34+H34+F34+D34 -> -314970.21
B35: 46053 | C35: 0 | D35: 0 | E35: 0 | F35: -9762.83 | G35: 0 | H35: 0 | I35: =+I34+C35+E35+G35+H35+F35+D35 -> -324733.04
B36: TOTAL | C36: =SUM(C5:C35) -> 0 | E36: =SUM(E5:E35) -> 0 | F36: =SUM(F5:F35) -> -324733.04 | G36: =SUM(G5:G35) -> 0 | H36: =SUM(H5:H35) -> 0
B38: Fevereiro-26
B39: DATA
C40: Entradas Realizadas | D40: Resgate apl | E40: Aporte Propietario | F40: Despesas realizadas | G40: Aplicação | H40: Shareholder Remuneration | I40: Saldo do dia
I41: =I35 -> -324733.04
...

Sheet VIP MX
A3: VIP MX | C3: 2026 | D3: 2026 | E3: 2026 | F3: 2026 | G3: 2026 | H3: 2026 | I3: 2026 | J3: 2026 | K3: 2026 | L3: 2026 | M3: 2026 | N3: 2026 | O3: 2026
C4: jan | D4: fev | E4: mar | F4: abr | G4: mai | H4: jun | I4: jul | J4: ago | K4: set | L4: out | M4: nov | N4: dez | O4: TOTAL
A5: ENTRADAS
A6: MERCADO LIVRE - VIP | O6: =SUM(C6:N6) -> 0
A7: AMAZON - VIP | O7: =SUM(C7:N7) -> 0
A8: SHOPEE - VIP | O8: =SUM(C8:N8) -> 0
A9: LOJA FISICA - VIP | O9: =SUM(C9:N9) -> 0
O11: =SUM(C11:N11) -> 0
O12: =SUM(C12:N12) -> 0
O13: =SUM(C13:N13) -> 0
O14: =SUM(C14:N14) -> 0
A15: TOTAL DE ENTRADAS | C15: =SUM(C6:C14) -> 0 | D15: =SUM(D6:D14) -> 0 | E15: =SUM(E6:E14) -> 0 | F15: =SUM(F6:F14) -> 0 | G15: =SUM(G6:G14) -> 0 | H15: =SUM(H6:H14) -> 0 | I15: =SUM(I6:I14) -> 0 | J15: =SUM(J6:J14) -> 0 | ... N15: =SUM(N6:N14) -> 0 | O15: =SUM(C15:N15) -> 0
A17: Impostos Diretos | C17: =SUM(C18:C25) -> 0 | D17: =SUM(D18:D25) -> 0 | E17: =SUM(E18:E25) -> 0 | F17: =SUM(F18:F25) -> 0 | G17: =SUM(G18:G25) -> 0 | H17: =SUM(H18:H25) -> 0 | I17: =SUM(I18:I25) -> 0 | J17: =SUM(J18:J25) -> 0 | ... N17: =SUM(N18:N25) -> 0 | O17: =SUM(C17:N17) -> 0
A18: PIS | O18: =SUM(C18:N18) -> 0
A19: COFINS | B19: 0.03 | O19: =SUM(C19:N19) -> 0
A20: IPI | O20: =SUM(C20:N20) -> 0
A21: CAMBIO
A22: IOF S/INVESTIMENTO
A23: IR S/INVESTIMENTO
A24: ICMS | O24: =SUM(C24:N24) -> 0
A25: ISS | O25: =SUM(C25:N25) -> 0
A27: DESPESAS COM PESSOAL E ENCARGOS | C27: =SUM(C28,C39,C46,C51,C73,C62,C66) -> 0 | D27: =SUM(D28,D39,D46,D51,D73,D62,D66) -> 0 | E27: =SUM(E28,E39,E46,E51,E73,E62,E66) -> 0 | F27: =SUM(F28,F39,F46,F51,F73,F62,F66) -> 0 | G27: =SUM(G28,G39,G46,G51,G73,G62,G66) -> 0 | H27: =SUM(H28,H39,H46,H51,H73,H62,H66) -> 0 | I27: =SUM(I28,I39,I46,I51,I73,I62,I66) -> 0 | J27: =SUM(J28,J39,J46,J51,J73,J62,J66) -> 0 | ... N27: =SUM(N28,N39,N46,N51,N73,N62,N66) -> 0 | O27: =SUM(C27:N27) -> 0
A28: Salários diretos | C28: =SUM(C29:C38) -> 0 | D28: =SUM(D29:D38) -> 0 | E28: =SUM(E29:E38) -> 0 | F28: =SUM(F29:F38) -> 0 | G28: =SUM(G29:G38) -> 0 | H28: =SUM(H29:H38) -> 0 | I28: =SUM(I29:I38) -> 0 | J28: =SUM(J29:J38) -> 0 | ... N28: =SUM(N29:N38) -> 0 | O28: =SUM(C28:N28) -> 0
A29: Salários diretos | O29: =SUM(C29:N29) -> 0
A30: Adiantamento salarial | O30: =SUM(C30:N30) -> 0
A31: Hora extra | O31: =SUM(C31:N31) -> 0
A32: Adicional noturno | O32: =SUM(C32:N32) -> 0
A33: 13o. salário | O33: =SUM(C33:N33) -> 0
A34: Férias | O34: =SUM(C34:N34) -> 0
A35: Gratificação / prêmio | O35: =SUM(C35:N35) -> 0
A36: Comissões | O36: =SUM(C36:N36) -> 0
A37: Pensão alimentícia | O37: =SUM(C37:N37) -> 0
A38: Transporte de Funcionários | O38: =SUM(C38:N38) -> 0
A39: Encargos trabalhistas | C39: =C40+C41+C42+C43+C44+C45 -> 0 | D39: =D40+D41+D42+D43+D44+D45 -> 0 | E39: =E40+E41+E42+E43+E44+E45 -> 0 | F39: =F40+F41+F42+F43+F44+F45 -> 0 | G39: =G40+G41+G42+G43+G44+G45 -> 0 | H39: =H40+H41+H42+H43+H44+H45 -> 0 | I39: =I40+I41+I42+I43+I44+I45 -> 0 | J39: =J40+J41+J42+J43+J44+J45 -> 0 | ... N39: =N40+N41+N42+N43+N44+N45 -> 0 | O39: =SUM(C39:N39) -> 0
A40: INSS | O40: =SUM(C40:N40) -> 0
A41: FGTS | O41: =SUM(C41:N41) -> 0
A42: IRRF | O42: =SUM(C42:N42) -> 0
A43: Contribuição/taxa sindical - Empregados | O43: =SUM(C43:N43) -> 0
A44: Contribuição/taxa sindical - Empresa | O44: =SUM(C44:N44) -> 0
A45: Dep. Judicial FGTS | O45: =SUM(C45:N45) -> 0
...

Sheet VIDAL
A3: VIDAL | C3: 2026 | D3: 2026 | E3: 2026 | F3: 2026 | G3: 2026 | H3: 2026 | I3: 2026 | J3: 2026 | K3: 2026 | L3: 2026 | M3: 2026 | N3: 2026 | O3: 2026
C4: jan | D4: fev | E4: mar | F4: abr | G4: mai | H4: jun | I4: jul | J4: ago | K4: set | L4: out | M4: nov | N4: dez | O4: TOTAL
A5: ENTRADAS
A6: MERCADO LIVRE - VIDAL | M6: 0 | N6: 0 | O6: =SUM(C6:N6) -> 0
A7: AMAZON - VIDAL | O7: =SUM(C7:N7) -> 0
A8: SHOPEE - VIDAL | O8: =SUM(C8:N8) -> 0
A9: LOJA FISICA - VIDAL | O9: =SUM(C9:N9) -> 0
O11: =SUM(C11:N11) -> 0
O12: =SUM(C12:N12) -> 0
O13: =SUM(C13:N13) -> 0
O14: =SUM(C14:N14) -> 0
A15: TOTAL DE ENTRADAS | C15: =SUM(C6:C14) -> 0 | D15: =SUM(D6:D14) -> 0 | E15: =SUM(E6:E14) -> 0 | F15: =SUM(F6:F14) -> 0 | G15: =SUM(G6:G14) -> 0 | H15: =SUM(H6:H14) -> 0 | I15: =SUM(I6:I14) -> 0 | J15: =SUM(J6:J14) -> 0 | ... N15: =SUM(N6:N14) -> 0 | O15: =SUM(C15:N15) -> 0
A17: Impostos Diretos | C17: =SUM(C18:C25) -> 0 | D17: =SUM(D18:D25) -> 0 | E17: =SUM(E18:E25) -> 0 | F17: =SUM(F18:F25) -> 0 | G17: =SUM(G18:G25) -> 0 | H17: =SUM(H18:H25) -> 0 | I17: =SUM(I18:I25) -> 0 | J17: =SUM(J18:J25) -> 0 | ... N17: =SUM(N18:N25) -> 0 | O17: =SUM(C17:N17) -> 0
A18: PIS | O18: =SUM(C18:N18) -> 0
A19: COFINS | B19: 0.03 | O19: =SUM(C19:N19) -> 0
A20: IPI | O20: =SUM(C20:N20) -> 0
A21: CAMBIO
A22: IOF S/INVESTIMENTO
A23: IR S/INVESTIMENTO
A24: ICMS | O24: =SUM(C24:N24) -> 0
A25: ISS | O25: =SUM(C25:N25) -> 0
A27: DESPESAS COM PESSOAL E ENCARGOS | C27: =SUM(C28,C39,C46,C51,C73,C62,C66) -> 0 | D27: =SUM(D28,D39,D46,D51,D73,D62,D66) -> 0 | E27: =SUM(E28,E39,E46,E51,E73,E62,E66) -> 0 | F27: =SUM(F28,F39,F46,F51,F73,F62,F66) -> 0 | G27: =SUM(G28,G39,G46,G51,G73,G62,G66) -> 0 | H27: =SUM(H28,H39,H46,H51,H73,H62,H66) -> 0 | I27: =SUM(I28,I39,I46,I51,I73,I62,I66) -> 0 | J27: =SUM(J28,J39,J46,J51,J73,J62,J66) -> 0 | ... N27: =SUM(N28,N39,N46,N51,N73,N62,N66) -> 0 | O27: =SUM(C27:N27) -> 0
A28: Salários diretos | C28: =SUM(C29:C38) -> 0 | D28: =SUM(D29:D38) -> 0 | E28: =SUM(E29:E38) -> 0 | F28: =SUM(F29:F38) -> 0 | G28: =SUM(G29:G38) -> 0 | H28: =SUM(H29:H38) -> 0 | I28: =SUM(I29:I38) -> 0 | J28: =SUM(J29:J38) -> 0 | ... N28: =SUM(N29:N38) -> 0 | O28: =SUM(C28:N28) -> 0
A29: Salários diretos | O29: =SUM(C29:N29) -> 0
A30: Adiantamento salarial | O30: =SUM(C30:N30) -> 0
A31: Hora extra | O31: =SUM(C31:N31) -> 0
A32: Adicional noturno | O32: =SUM(C32:N32) -> 0
A33: 13o. salário | O33: =SUM(C33:N33) -> 0
A34: Férias | O34: =SUM(C34:N34) -> 0
A35: Gratificação / prêmio | O35: =SUM(C35:N35) -> 0
A36: Comissões | O36: =SUM(C36:N36) -> 0
A37: Pensão alimentícia | O37: =SUM(C37:N37) -> 0
A38: Transporte de Funcionários | O38: =SUM(C38:N38) -> 0
A39: Encargos trabalhistas | C39: =C40+C41+C42+C43+C44+C45 -> 0 | D39: =D40+D41+D42+D43+D44+D45 -> 0 | E39: =E40+E41+E42+E43+E44+E45 -> 0 | F39: =F40+F41+F42+F43+F44+F45 -> 0 | G39: =G40+G41+G42+G43+G44+G45 -> 0 | H39: =H40+H41+H42+H43+H44+H45 -> 0 | I39: =I40+I41+I42+I43+I44+I45 -> 0 | J39: =J40+J41+J42+J43+J44+J45 -> 0 | ... N39: =N40+N41+N42+N43+N44+N45 -> 0 | O39: =SUM(C39:N39) -> 0
A40: INSS | O40: =SUM(C40:N40) -> 0
A41: FGTS | O41: =SUM(C41:N41) -> 0
A42: IRRF | O42: =SUM(C42:N42) -> 0
A43: Contribuição/taxa sindical - Empregados | O43: =SUM(C43:N43) -> 0
A44: Contribuição/taxa sindical - Empresa | O44: =SUM(C44:N44) -> 0
A45: Dep. Judicial FGTS | O45: =SUM(C45:N45) -> 0
...

Sheet V3
A3: V3 | C3: 2026 | D3: 2026 | E3: 2026 | F3: 2026 | G3: 2026 | H3: 2026 | I3: 2026 | J3: 2026 | K3: 2026 | L3: 2026 | M3: 2026 | N3: 2026 | O3: 2026
C4: jan | D4: fev | E4: mar | F4: abr | G4: mai | H4: jun | I4: jul | J4: ago | K4: set | L4: out | M4: nov | N4: dez | O4: TOTAL
A5: ENTRADAS
A6: MERCADO LIVRE - V3 | O6: =SUM(C6:N6) -> 0
A7: AMAZON - V3 | O7: =SUM(C7:N7) -> 0
A8: SHOPEE - V3 | O8: =SUM(C8:N8) -> 0
A9: LOJA FISICA - V3 | O9: =SUM(C9:N9) -> 0
O11: =SUM(C11:N11) -> 0
O12: =SUM(C12:N12) -> 0
O13: =SUM(C13:N13) -> 0
O14: =SUM(C14:N14) -> 0
A15: TOTAL DE ENTRADAS | C15: =SUM(C6:C14) -> 0 | D15: =SUM(D6:D14) -> 0 | E15: =SUM(E6:E14) -> 0 | F15: =SUM(F6:F14) -> 0 | G15: =SUM(G6:G14) -> 0 | H15: =SUM(H6:H14) -> 0 | I15: =SUM(I6:I14) -> 0 | J15: =SUM(J6:J14) -> 0 | ... N15: =SUM(N6:N14) -> 0 | O15: =SUM(C15:N15) -> 0
A17: Impostos Diretos | C17: =SUM(C18:C25) -> 0 | D17: =SUM(D18:D25) -> 0 | E17: =SUM(E18:E25) -> 0 | F17: =SUM(F18:F25) -> 0 | G17: =SUM(G18:G25) -> 0 | H17: =SUM(H18:H25) -> 0 | I17: =SUM(I18:I25) -> 0 | J17: =SUM(J18:J25) -> 0 | ... N17: =SUM(N18:N25) -> 0 | O17: =SUM(C17:N17) -> 0
A18: PIS | O18: =SUM(C18:N18) -> 0
A19: COFINS | B19: 0.03 | O19: =SUM(C19:N19) -> 0
A20: IPI | O20: =SUM(C20:N20) -> 0
A21: CAMBIO
A22: IOF S/INVESTIMENTO
A23: IR S/INVESTIMENTO
A24: ICMS | O24: =SUM(C24:N24) -> 0
A25: ISS | O25: =SUM(C25:N25) -> 0
A27: DESPESAS COM PESSOAL E ENCARGOS | C27: =SUM(C28,C39,C46,C51,C73,C62,C66) -> 0 | D27: =SUM(D28,D39,D46,D51,D73,D62,D66) -> 0 | E27: =SUM(E28,E39,E46,E51,E73,E62,E66) -> 0 | F27: =SUM(F28,F39,F46,F51,F73,F62,F66) -> 0 | G27: =SUM(G28,G39,G46,G51,G73,G62,G66) -> 0 | H27: =SUM(H28,H39,H46,H51,H73,H62,H66) -> 0 | I27: =SUM(I28,I39,I46,I51,I73,I62,I66) -> 0 | J27: =SUM(J28,J39,J46,J51,J73,J62,J66) -> 0 | ... N27: =SUM(N28,N39,N46,N51,N73,N62,N66) -> 0 | O27: =SUM(C27:N27) -> 0
A28: Salários diretos | C28: =SUM(C29:C38) -> 0 | D28: =SUM(D29:D38) -> 0 | E28: =SUM(E29:E38) -> 0 | F28: =SUM(F29:F38) -> 0 | G28: =SUM(G29:G38) -> 0 | H28: =SUM(H29:H38) -> 0 | I28: =SUM(I29:I38) -> 0 | J28: =SUM(J29:J38) -> 0 | ... N28: =SUM(N29:N38) -> 0 | O28: =SUM(C28:N28) -> 0
A29: Salários diretos | O29: =SUM(C29:N29) -> 0
A30: Adiantamento salarial | O30: =SUM(C30:N30) -> 0
A31: Hora extra | O31: =SUM(C31:N31) -> 0
A32: Adicional noturno | O32: =SUM(C32:N32) -> 0
A33: 13o. salário | O33: =SUM(C33:N33) -> 0
A34: Férias | O34: =SUM(C34:N34) -> 0
A35: Gratificação / prêmio | O35: =SUM(C35:N35) -> 0
A36: Comissões | O36: =SUM(C36:N36) -> 0
A37: Pensão alimentícia | O37: =SUM(C37:N37) -> 0
A38: Transporte de Funcionários | O38: =SUM(C38:N38) -> 0
A39: Encargos trabalhistas | C39: =C40+C41+C42+C43+C44+C45 -> 0 | D39: =D40+D41+D42+D43+D44+D45 -> 0 | E39: =E40+E41+E42+E43+E44+E45 -> 0 | F39: =F40+F41+F42+F43+F44+F45 -> 0 | G39: =G40+G41+G42+G43+G44+G45 -> 0 | H39: =H40+H41+H42+H43+H44+H45 -> 0 | I39: =I40+I41+I42+I43+I44+I45 -> 0 | J39: =J40+J41+J42+J43+J44+J45 -> 0 | ... N39: =N40+N41+N42+N43+N44+N45 -> 0 | O39: =SUM(C39:N39) -> 0
A40: INSS | O40: =SUM(C40:N40) -> 0
A41: FGTS | O41: =SUM(C41:N41) -> 0
A42: IRRF | O42: =SUM(C42:N42) -> 0
A43: Contribuição/taxa sindical - Empregados | O43: =SUM(C43:N43) -> 0
A44: Contribuição/taxa sindical - Empresa | O44: =SUM(C44:N44) -> 0
A45: Dep. Judicial FGTS | O45: =SUM(C45:N45) -> 0
...

Sheet Fluxo De caixa - VIP 12-2025
B1: DEZEMBRO-2025
B2: DATA
C3: Entradas Realizadas | D3: Resgate apl | E3: Aporte Propietario | F3: Despesas realizadas | G3: Aplicação | H3: Shareholder Remuneration | I3: Saldo do dia
I4: =30408.29+4336.3 -> 34744.59
B5: 46013 | C5: 45000 | D5: 0 | E5: 0 | F5: =-(29955.91+28232.08+600) -> -58787.99 | G5: 0 | H5: 0 | I5: =+I4+C5+E5+G5+H5+F5+D5 -> 20956.6
B6: 46014 | C6: 0 | D6: 0 | E6: 0 | F6: -6927.9 | G6: 0 | H6: 0 | I6: =+I5+C6+E6+G6+H6+F6+D6 -> 14028.7
B7: 46015 | C7: 0 | D7: 0 | E7: 0 | F7: -6890.19 | G7: 0 | H7: 0 | I7: =+I6+C7+E7+G7+H7+F7+D7 -> 7138.51
B8: 46016 | C8: 0 | D8: 0 | E8: 0 | F8: -10708.48 | G8: 0 | H8: 0 | I8: =+I7+C8+E8+G8+H8+F8+D8 -> -3569.97
B9: 46017 | C9: 0 | D9: 0 | E9: 0 | F9: -10740.8 | G9: 0 | H9: 0 | I9: =+I8+C9+E9+G9+H9+F9+D9 -> -14310.77
B10: 46018 | C10: 0 | D10: 0 | E10: 0 | F10: -9988.89 | G10: 0 | H10: 0 | I10: =+I9+C10+E10+G10+H10+F10+D10 -> -24299.66
B11: 46019 | C11: 0 | D11: 0 | E11: 0 | F11: -4414.47 | G11: 0 | H11: 0 | I11: =+I10+C11+E11+G11+H11+F11+D11 -> -28714.13
B12: 46020 | C12: =30147.01+33984.23 -> 64131.24 | D12: 0 | E12: 0 | F12: -10476.48 | G12: 0 | H12: 0 | I12: =+I11+C12+E12+G12+H12+F12+D12 -> 24940.63
B13: 46021 | C13: 0 | D13: 0 | E13: 0 | F13: =-(1000+11215.16) -> -12215.16 | G13: 0 | H13: 0 | I13: =+I12+C13+E13+G13+H13+F13+D13 -> 12725.47
B14: 46022 | C14: 0 | D14: 0 | E14: 0 | F14: -8066.43 | G14: 0 | H14: 0 | I14: =+I13+C14+E14+G14+H14+F14+D14 -> 4659.04
B15: TOTAL | C15: =SUM(C6:C14) -> 64131.24 | E15: =SUM(E6:E14) -> 0 | F15: =SUM(F6:F14) -> -80428.8 | G15: =SUM(G6:G14) -> 0 | H15: =SUM(H6:H14) -> 0

Sheet Ações 2026
B3: AÇÕES IMPORTANTES
B5: Mês | C5: Ação | D5: Status | E5: Definição | F5: Gasto Previsto | G5: Gasto Realizado
B7: 46023 | C7: Definição da contabilidade | D7: Finalizado | E7: Manter a contabilidade atual até o fim de Junho. | F7: 0 | G7: 0
B8: 46023 | C8: Definição de instituição bancaria para o Grupo | D8: Finalizado | E8: Brasil e Sicoob | F8: 0 | G8: 0
B9: 46023 | C9: Abertura de Conta VIP | D9: Finalizado | E9: Banco Brasil | F9: 0 | G9: 0
B10: 46023 | C10: Abertura de Conta Vidal | D10: Finalizado | E10: Banco Sicoob | F10: 0 | G10: 0
B11: 46023 | C11: Definição de empresa de alavancagem de vendas ML | D11: Não Iniciado | F11: 0 | G11: 0
B12: 46023 | C12: Preparação novo colaborador | D12: Não Iniciado | F12: =180+230+900+150 -> 1460 | G12: 0
B13: 46023 | C13: Criação e Validação do Relatorio de vendas | D13: Não Iniciado | F13: 0 | G13: 0
B14: 46023 | C14: Fechamento Caixa LF | D14: Não Iniciado | F14: 0 | G14: 0
B15: 46023 | C15: Alteração ponto Fisico de Vip para Vidal | D15: Não Iniciado | E15: Vidal para Dolomita5 | F15: 0 | G15: 0
B16: 46023 | C16: Criação perfil vaga de Auxiliar administrativo | D16: Não Iniciado | F16: 0 | G16: 0
B17: 46023 | C17: Validação com o Bling processo de estoque | D17: Não Iniciado | F17: 0 | G17: 0
B18: 46054 | C18: Implementar Registro de Ponto | D18: Não Iniciado | F18: 250 | G18: 0
F19: =SUM(F7:F18) -> 1710 | G19: =SUM(G7:G18) -> 0
B21: 46054 | C21: Processo Seletivo Novo Colaborador | D21: Não Iniciado | F21: 0 | G21: 0
B22: 46054 | C22: Contratação | D22: Não Iniciado | F22: 0 | G22: 0
B23: 46054 | C23: Inventario Estoque | D23: Não Iniciado | F23: 0 | G23: 0
B24: 46054 | C24: Separação Estoque VIP e VIDAL | D24: Não Iniciado | F24: 0 | G24: 0
B25: 46054 | C25: Definição de Metas - Equipe | D25: Não Iniciado | F25: 0 | G25: 0
F30: =SUM(F21:F29) -> 0 | G30: =SUM(G21:G29) -> 0

Sheet Divida Fornecedores
B2: CONTAS PAGAS | K2: CONTAS A PAGAR
B4: VIP | F4: VIDAL | K4: VIP | O4: VIDAL
B6: Mês | C6: Valor | F6: Mês | G6: Valor | K6: Mês | L6: Valor | O6: Mês | P6: Valor
B7: 46023 | C7: 252772.95 | F7: 46023 | G7: 0 | K7: 46023 | L7: 0 | O7: 46023 | P7: 0
B8: 46054 | C8: 228525.11 | F8: 46054 | G8: 3059 | K8: 46054 | L8: 0 | O8: 46054 | P8: 0
B9: 46082 | C9: 268703.5 | F9: 46082 | G9: 10570.07 | K9: 46082 | L9: 0 | O9: 46082 | P9: 1116.63
B10: 46113 | C10: 223982.07 | F10: 46113 | G10: 30495.45 | K10: 46113 | L10: 0 | O10: 46113 | P10: 0
B11: 46143 | C11: 319945.38 | F11: 46143 | G11: 52752.71 | K11: 46143 | L11: 0 | O11: 46143 | P11: 0
B12: 46174 | C12: 71959.33 | F12: 46174 | G12: 4702.05 | K12: 46174 | L12: 242737.6 | O12: 46174 | P12: 34120.22
B13: 46204 | C13: 0 | F13: 46204 | G13: 0 | K13: 46204 | L13: 279660.9 | O13: 46204 | P13: 26388.28
B14: 46235 | C14: 0 | F14: 46235 | G14: 0 | K14: 46235 | L14: 193891.55 | O14: 46235 | P14: 0
B15: 46266 | C15: 0 | F15: 46266 | G15: 0 | K15: 46266 | L15: 112354.99 | O15: 46266 | P15: 0
B16: 46296 | C16: 0 | F16: 46296 | G16: 0 | K16: 46296 | L16: 50055.49 | O16: 46296 | P16: 0
B17: 46327 | C17: 0 | F17: 46327 | G17: 0 | K17: 46327 | L17: 18763.44 | O17: 46327 | P17: 0
B18: 46357 | C18: 0 | F18: 46357 | G18: 0 | K18: 46357 | L18: 0 | O18: 46357 | P18: 0
B19: Total: | C19: =SUM(C7:C18) -> 1365888.3 | F19: Total: | G19: =SUM(G7:G18) -> 101579.28 | K19: Total: | L19: =SUM(L7:L18) -> 897463.97 | O19: Total: | P19: =SUM(P7:P18) -> 61625.13

Sheet Feira Santana
